Traceback (most recent call last):
  File "/Library/Frameworks/Python.framework/Versions/3.12/lib/python3.12/site-packages/jupyter_cache/executors/utils.py", line 58, in single_nb_execution
    executenb(
  File "/Library/Frameworks/Python.framework/Versions/3.12/lib/python3.12/site-packages/nbclient/client.py", line 1314, in execute
    return NotebookClient(nb=nb, resources=resources, km=km, **kwargs).execute()
           ^^^^^^^^^^^^^^^^^^^^^^^^^^^^^^^^^^^^^^^^^^^^^^^^^^^^^^^^^^^^^^^^^^^^^
  File "/Library/Frameworks/Python.framework/Versions/3.12/lib/python3.12/site-packages/jupyter_core/utils/__init__.py", line 165, in wrapped
    return loop.run_until_complete(inner)
           ^^^^^^^^^^^^^^^^^^^^^^^^^^^^^^
  File "/Library/Frameworks/Python.framework/Versions/3.12/lib/python3.12/asyncio/base_events.py", line 684, in run_until_complete
    return future.result()
           ^^^^^^^^^^^^^^^
  File "/Library/Frameworks/Python.framework/Versions/3.12/lib/python3.12/site-packages/nbclient/client.py", line 709, in async_execute
    await self.async_execute_cell(
  File "/Library/Frameworks/Python.framework/Versions/3.12/lib/python3.12/site-packages/nbclient/client.py", line 1062, in async_execute_cell
    await self._check_raise_for_error(cell, cell_index, exec_reply)
  File "/Library/Frameworks/Python.framework/Versions/3.12/lib/python3.12/site-packages/nbclient/client.py", line 918, in _check_raise_for_error
    raise CellExecutionError.from_cell_and_msg(cell, exec_reply_content)
nbclient.exceptions.CellExecutionError: An error occurred while executing the following cell:
------------------
# Setup (pretty display and imports)
import pandas as pd
pd.set_option("display.max_colwidth", 80)
pd.set_option("display.precision", 0)

from utils import dracor_client as dc
from datetime import datetime
print("Last run:", datetime.utcnow().strftime("%Y-%m-%d %H:%M UTC"))
------------------


[0;31m---------------------------------------------------------------------------[0m
[0;31mModuleNotFoundError[0m                       Traceback (most recent call last)
Cell [0;32mIn[1], line 6[0m
[1;32m      3[0m pd[38;5;241m.[39mset_option([38;5;124m"[39m[38;5;124mdisplay.max_colwidth[39m[38;5;124m"[39m, [38;5;241m80[39m)
[1;32m      4[0m pd[38;5;241m.[39mset_option([38;5;124m"[39m[38;5;124mdisplay.precision[39m[38;5;124m"[39m, [38;5;241m0[39m)
[0;32m----> 6[0m [38;5;28;01mfrom[39;00m [38;5;21;01mutils[39;00m [38;5;28;01mimport[39;00m dracor_client [38;5;28;01mas[39;00m dc
[1;32m      7[0m [38;5;28;01mfrom[39;00m [38;5;21;01mdatetime[39;00m [38;5;28;01mimport[39;00m datetime
[1;32m      8[0m [38;5;28mprint[39m([38;5;124m"[39m[38;5;124mLast run:[39m[38;5;124m"[39m, datetime[38;5;241m.[39mutcnow()[38;5;241m.[39mstrftime([38;5;124m"[39m[38;5;124m%[39m[38;5;124mY-[39m[38;5;124m%[39m[38;5;124mm-[39m[38;5;132;01m%d[39;00m[38;5;124m [39m[38;5;124m%[39m[38;5;124mH:[39m[38;5;124m%[39m[38;5;124mM UTC[39m[38;5;124m"[39m))

[0;31mModuleNotFoundError[0m: No module named 'utils'

